Workbook

Sheet Instrucciones
A1: CÓMO USAR ESTE ARCHIVO
A3: 1. Cada día
A4: Abre tu excel de despachos y entra a la hoja "Resumen".
A6: 2. Copia
A7: Selecciona PRODUCTO, SKU y TOTAL CONTABILIZADO de esa hoja.
A9: 3. Pega
A10: Ve a la hoja "Pegar Despachos" de este archivo y pega debajo de la última fila usada (columnas B, C, D). Escribe la fecha en A. El orden no importa, cada fila descuenta por su SKU.
A12: 4. Listo
A13: La hoja "Stock" ya muestra el STOCK ACTUAL descontado y AVERIADOS, sin nada más.
A15: 5. Buscar
A16: En "Stock", a la derecha hay un buscador: escribe un SKU o parte del nombre y salen los datos de ese producto.
A18: 6. Series y MAC
... A22: El STOCK INICIAL vive en la hoja "Stock Base", separado, para que no lo veas en tu día a día. Solo entra ahí si necesitas corregir el conteo de partida.

Sheet Stock
A1: MI STOCK
A2: Se descuenta solo con lo que pegues en la hoja "Pegar Despachos".
A4: PRODUCTO | B4: SKU | C4: UDM | D4: STOCK ACTUAL | E4: AVERIADOS | G4: BUSCADOR DE STOCK
A5: ATADOR DE IDENTIFICACION DE ABONADO | B5: 1002950 | C5: UNIDADES | D5: ='Stock Base'!D5-SUMIF('Pegar Despachos'!$C:$C,$B5,'Pegar Despachos'!$D:$D) -> 1433 | E5: ='Stock Base'!E5 -> 0
A6: CABLE COAXIAL BLANCO RG-6 S/MENSAJERO | B6: 1004705 | C6: METROS | D6: ='Stock Base'!D6-SUMIF('Pegar Despachos'!$C:$C,$B6,'Pegar Despachos'!$D:$D) -> 2816 | E6: ='Stock Base'!E6 -> 0 | G6: Buscar (SKU o nombre):
A7: CABLE COAXIAL RG-6 AUTOSOPORTADO | B7: 1003101 | C7: METROS | D7: ='Stock Base'!D7-SUMIF('Pegar Despachos'!$C:$C,$B7,'Pegar Despachos'!$D:$D) -> 6787 | E7: ='Stock Base'!E7 -> 0 | G7: Fila encontrada (uso interno, no borrar): | H7: =IF(H6="","",IFERROR(MATCH(H6,Stock!$B$5:$B$57,0),IFERROR(MATCH("*"&H6&"*",Stock!$A$5:$A$57,0),"")))
A8: CABLE FO DROP REDONDO CTC-0066 5MM 10MTS | B8: 1059757 | C8: UNIDADES | D8: ='Stock Base'!D8-SUMIF('Pegar Despachos'!$C:$C,$B8,'Pegar Despachos'!$D:$D) -> 35 | E8: ='Stock Base'!E8 -> 0 | G8: Producto: | H8: =IFERROR(INDEX(Stock!$A$5:$A$57,H7),"No encontrado") -> No encontrado
A9: CABLE FO ECS DROP 300M ECOSS | B9: 1062235 | C9: METROS | D9: ='Stock Base'!D9-SUMIF('Pegar Despachos'!$C:$C,$B9,'Pegar Despachos'!$D:$D) -> 1954 | E9: ='Stock Base'!E9 -> 0 | G9: SKU: | H9: =IFERROR(INDEX(Stock!$B$5:$B$57,H7),"No encontrado") -> No encontrado
A10: CABLE FO FASTCONNECT DROP 14138979 100M | B10: 1062885 | C10: UNIDADES | D10: ='Stock Base'!D10-SUMIF('Pegar Despachos'!$C:$C,$B10,'Pegar Despachos'!$D:$D) -> 52 | E10: ='Stock Base'!E10 -> 0 | G10: UdM: | H10: =IFERROR(INDEX(Stock!$C$5:$C$57,H7),"No encontrado") -> No encontrado
A11: CABLE FO FASTCONNECT DROP 14138979 150M | B11: 1062886 | C11: UNIDADES | D11: ='Stock Base'!D11-SUMIF('Pegar Despachos'!$C:$C,$B11,'Pegar Despachos'!$D:$D) -> 92 | E11: ='Stock Base'!E11 -> 0 | G11: Stock Actual: | H11: =IFERROR(INDEX(Stock!$D$5:$D$57,H7),"No encontrado") -> No encontrado
A12: CABLE FO FASTCONNECT DROP 14138979 220M | B12: 1062887 | C12: UNIDADES | D12: ='Stock Base'!D12-SUMIF('Pegar Despachos'!$C:$C,$B12,'Pegar Despachos'!$D:$D) -> 112 | E12: ='Stock Base'!E12 -> 0 | G12: Averiados: | H12: =IFERROR(INDEX(Stock!$E$5:$E$57,H7),"No encontrado") -> No encontrado
A13: CABLE FO FASTCONNECT DROP 14138979 300M | B13: 1063812 | C13: UNIDADES | D13: ='Stock Base'!D13-SUMIF('Pegar Despachos'!$C:$C,$B13,'Pegar Despachos'!$D:$D) -> 18 | E13: ='Stock Base'!E13 -> 0
A14: CABLE FO FASTCONNECT DROP 14138979 50M | B14: 1062883 | C14: UNIDADES | D14: ='Stock Base'!D14-SUMIF('Pegar Despachos'!$C:$C,$B14,'Pegar Despachos'!$D:$D) -> 182 | E14: ='Stock Base'!E14 -> 0 | G14: Escribe el SKU exacto o parte del nombre del producto y arriba se llenan los datos.
A15: CABLE FO FASTCONNECT DROP 14138979 80M | B15: 1062884 | C15: UNIDADES | D15: ='Stock Base'!D15-SUMIF('Pegar Despachos'!$C:$C,$B15,'Pegar Despachos'!$D:$D) -> 129 | E15: ='Stock Base'!E15 -> 0
A16: CABLE FO PATCH CORD SC/APC ECOSS 1.5 M | B16: 1061257 | C16: UNIDADES | D16: ='Stock Base'!D16-SUMIF('Pegar Despachos'!$C:$C,$B16,'Pegar Despachos'!$D:$D) -> 27 | E16: ='Stock Base'!E16 -> 0
A17: CABLE HDMI 1.5M 4K V2 SOLYA | B17: 1067962 | C17: UNIDADES | D17: ='Stock Base'!D17-SUMIF('Pegar Despachos'!$C:$C,$B17,'Pegar Despachos'!$D:$D) -> 134 | E17: ='Stock Base'!E17 -> 0
A18: CABLE HDMI CHD1-6 MALE TO MALE 2M | B18: 1004838 | C18: UNIDADES | D18: ='Stock Base'!D18-SUMIF('Pegar Despachos'!$C:$C,$B18,'Pegar Despachos'!$D:$D) -> 1 | E18: ='Stock Base'!E18 -> 0
A19: CABLE TELEF INTERIOR 2/22 AWG | B19: 1004703 | C19: UNIDADES | D19: ='Stock Base'!D19-SUMIF('Pegar Despachos'!$C:$C,$B19,'Pegar Despachos'!$D:$D) -> 17 | E19: ='Stock Base'!E19 -> 0
A20: CABLE TELEF INTERIOR 2/22 AWG | B20: 1033042 | C20: METROS | D20: ='Stock Base'!D20-SUMIF('Pegar Despachos'!$C:$C,$B20,'Pegar Despachos'!$D:$D) -> 2 | E20: ='Stock Base'!E20 -> 0
A21: CABLE UTP CAT5E FTP 4PR/24AWG 04070009 | B21: 1004692 | C21: METROS | D21: ='Stock Base'!D21-SUMIF('Pegar Despachos'!$C:$C,$B21,'Pegar Despachos'!$D:$D) -> 15909 | E21: ='Stock Base'!E21 -> 0
A22: CAJA DE EMPALME DROP BOX-1 QTK | B22: 1063891 | C22: UNIDADES | D22: ='Stock Base'!D22-SUMIF('Pegar Despachos'!$C:$C,$B22,'Pegar Despachos'!$D:$D) -> 23 | E22: ='Stock Base'!E22 -> 0
A23: CONECTOR DE CONTINUIDAD RG6 EX6XL-PLUS | B23: 1062712 | C23: UNIDADES | D23: ='Stock Base'!D23-SUMIF('Pegar Despachos'!$C:$C,$B23,'Pegar Despachos'!$D:$D) -> 2280 | E23: ='Stock Base'!E23 -> 0
A24: CONECTOR FIBRA OPTICA FTTH PPC | B24: 1066118 | C24: UNIDADES | D24: ='Stock Base'!D24-SUMIF('Pegar Despachos'!$C:$C,$B24,'Pegar Despachos'!$D:$D) -> 1958 | E24: ='Stock Base'!E24 -> 0
A25: CONECTOR PLUG RJ-45 | B25: 1002900 | C25: UNIDADES | D25: ='Stock Base'!D25-SUMIF('Pegar Despachos'!$C:$C,$B25,'Pegar Despachos'!$D:$D) -> 2631 | E25: ='Stock Base'!E25 -> 0
A26: CONECTOR RJ 11 | B26: 1063021 | C26: UNIDADES | D26: ='Stock Base'!D26-SUMIF('Pegar Despachos'!$C:$C,$B26,'Pegar Despachos'!$D:$D) -> 196 | E26: ='Stock Base'!E26 -> 0
... A57: TELEFONO ECS622 ECOSS | B57: 1053621 | C57: UNIDADES | D57: ='Stock Base'!D57-SUMIF('Pegar Despachos'!$C:$C,$B57,'Pegar Despachos'!$D:$D) -> 492 | E57: ='Stock Base'!E57 -> 0

Sheet Pegar Despachos
A1: PEGAR DESPACHOS AQUÍ
A2: Cada día: en tu excel de despachos, hoja "Resumen", copia PRODUCTO, SKU y TOTAL CONTABILIZADO, y pégalo debajo de la última fila usada (columnas B, C, D). Escribe la fecha en A. No se borra nada de "Stock": esta hoja solo suma, y "Stock" descuenta solo por SKU.
A4: FECHA | B4: PRODUCTO | C4: SKU | D4: CANTIDAD DESPACHADA
A5: 46246 | B5: CONECTOR PLUG RJ-45 | C5: 1002900 | D5: 137
A6: 46246 | B6: ATADOR DE IDENTIFICACION DE ABONADO | C6: 1002950 | D6: 42
A7: 46246 | B7: CABLE UTP CAT5E FTP 4PR/24AWG 04070009 | C7: 1004692 | D7: 12
A8: 46246 | B8: ROSETA ATB3101 SIN PIGTAIL | C8: 1042681 | D8: 30
A9: 46246 | B9: TELEFONO ECS622 ECOSS | C9: 1053621 | D9: 16
A10: 46246 | B10: CABLE FO FASTCONNECT DROP 14138979 80M | C10: 1062884 | D10: 13
A11: 46246 | B11: CABLE FO FASTCONNECT DROP 14138979 100M | C11: 1062885 | D11: 4
A12: 46246 | B12: CABLE FO FASTCONNECT DROP 14138979 150M | C12: 1062886 | D12: 6
A13: 46246 | B13: CONTROL REMOTO C3401 180000518128 ZTE | C13: 1063890 | D13: 61
A14: 46246 | B14: CONECTOR FIBRA OPTICA FTTH PPC | C14: 1066118 | D14: 41
A15: 46246 | B15: CABLE HDMI 1.5M 4K V2 SOLYA | C15: 1067962 | D15: 66
A16: 46246 | B16: DECODIFICADOR IPTV ZXV10 B866V2-H ZTE | C16: 4072704 | D16: 67
... A32: 46246 | B32: TARUGO NYLON 3/8 NARANJA | C32: MATE-0020 | D32: 2

Sheet Stock Base
A1: STOCK BASE (punto de partida)
A2: Esto es lo único que alimenta el cálculo de "Stock". No lo necesitas ver día a día -- la hoja "Stock" ya te muestra el resultado. Solo entra aquí si necesitas corregir el conteo base.
A4: PRODUCTO | B4: SKU | C4: UDM | D4: STOCK INICIAL | E4: AVERIADOS
A5: ATADOR DE IDENTIFICACION DE ABONADO | B5: 1002950 | C5: UNIDADES | D5: 1475 | E5: 0
A6: CABLE COAXIAL BLANCO RG-6 S/MENSAJERO | B6: 1004705 | C6: METROS | D6: 3121 | E6: 0
A7: CABLE COAXIAL RG-6 AUTOSOPORTADO | B7: 1003101 | C7: METROS | D7: 6794 | E7: 0
A8: CABLE FO DROP REDONDO CTC-0066 5MM 10MTS | B8: 1059757 | C8: UNIDADES | D8: 35 | E8: 0
A9: CABLE FO ECS DROP 300M ECOSS | B9: 1062235 | C9: METROS | D9: 1954 | E9: 0
A10: CABLE FO FASTCONNECT DROP 14138979 100M | B10: 1062885 | C10: UNIDADES | D10: 56 | E10: 0
A11: CABLE FO FASTCONNECT DROP 14138979 150M | B11: 1062886 | C11: UNIDADES | D11: 98 | E11: 0
A12: CABLE FO FASTCONNECT DROP 14138979 220M | B12: 1062887 | C12: UNIDADES | D12: 116 | E12: 0
A13: CABLE FO FASTCONNECT DROP 14138979 300M | B13: 1063812 | C13: UNIDADES | D13: 20 | E13: 0
A14: CABLE FO FASTCONNECT DROP 14138979 50M | B14: 1062883 | C14: UNIDADES | D14: 189 | E14: 0
A15: CABLE FO FASTCONNECT DROP 14138979 80M | B15: 1062884 | C15: UNIDADES | D15: 142 | E15: 0
A16: CABLE FO PATCH CORD SC/APC ECOSS 1.5 M | B16: 1061257 | C16: UNIDADES | D16: 29 | E16: 0
... A57: TELEFONO ECS622 ECOSS | B57: 1053621 | C57: UNIDADES | D57: 508 | E57: 0

Sheet Equipos (Series-MAC)
A1: EQUIPOS — SERIES Y MAC
A2: Una sección por producto (routers, módems, decodificadores, etc.). Ya cargué las series reales de tu último despacho. Pega debajo de cada sección las siguientes, con SERIE, MAC EMTA y MAC UA. Los materiales sin código (cables, conectores, rosetas, etc.) no van aquí, esos se controlan por cantidad en la hoja "Stock".
A4: DECODIFICADOR IPTV ZXV10 B866V2-H ZTE (SKU 4072704)
A5: PRODUCTO | B5: SKU | C5: SERIE | D5: MAC EMTA | E5: MAC UA
A6: DECODIFICADOR IPTV ZXV10 B866V2-H ZTE | B6: 4072704 | C6: ZTEATV45500711434
A7: DECODIFICADOR IPTV ZXV10 B866V2-H ZTE | B7: 4072704 | C7: ZTEATV45501900548
A8: DECODIFICADOR IPTV ZXV10 B866V2-H ZTE | B8: 4072704 | C8: ZTEATV45500710319
A9: DECODIFICADOR IPTV ZXV10 B866V2-H ZTE | B9: 4072704 | C9: ZTEATV45500713852
A10: DECODIFICADOR IPTV ZXV10 B866V2-H ZTE | B10: 4072704 | C10: ZTEATV45501144257
A11: DECODIFICADOR IPTV ZXV10 B866V2-H ZTE | B11: 4072704 | C11: ZTEATV45501145012
A12: DECODIFICADOR IPTV ZXV10 B866V2-H ZTE | B12: 4072704 | C12: ZTEATV45501957446
A13: DECODIFICADOR IPTV ZXV10 B866V2-H ZTE | B13: 4072704 | C13: ZTEATV45500505396
A14: DECODIFICADOR IPTV ZXV10 B866V2-H ZTE | B14: 4072704 | C14: ZTEATV45501123241
A15: DECODIFICADOR IPTV ZXV10 B866V2-H ZTE | B15: 4072704 | C15: ZTEATV45501155162
A16: DECODIFICADOR IPTV ZXV10 B866V2-H ZTE | B16: 4072704 | C16: ZTEATV45501159720
A17: DECODIFICADOR IPTV ZXV10 B866V2-H ZTE | B17: 4072704 | C17: ZTEATV45501940500
... A67: DECODIFICADOR IPTV ZXV10 B866V2-H ZTE | B67: 4072704 | C67: ZTEATV45501950899
A68: DECODIFICADOR IPTV ZXV10 B866V2-H ZTE | B68: 4072704
A69: DECODIFICADOR IPTV ZXV10 B866V2-H ZTE | B69: 4072704
A70: DECODIFICADOR IPTV ZXV10 B866V2-H ZTE | B70: 4072704
A71: DECODIFICADOR IPTV ZXV10 B866V2-H ZTE | B71: 4072704
A72: DECODIFICADOR IPTV ZXV10 B866V2-H ZTE | B72: 4072704
A73: DECODIFICADOR IPTV ZXV10 B866V2-H ZTE | B73: 4072704
A74: DECODIFICADOR IPTV ZXV10 B866V2-H ZTE | B74: 4072704
A75: DECODIFICADOR IPTV ZXV10 B866V2-H ZTE | B75: 4072704
A77: DECODIFICADOR MOTOROLA DVR DCX-3520 (SKU 4007967)
A78: PRODUCTO | B78: SKU | C78: SERIE | D78: MAC EMTA | E78: MAC UA
A79: DECODIFICADOR MOTOROLA DVR DCX-3520 | B79: 4007967
A80: DECODIFICADOR MOTOROLA DVR DCX-3520 | B80: 4007967
A81: DECODIFICADOR MOTOROLA DVR DCX-3520 | B81: 4007967
A82: DECODIFICADOR MOTOROLA DVR DCX-3520 | B82: 4007967
A83: DECODIFICADOR MOTOROLA DVR DCX-3520 | B83: 4007967
A84: DECODIFICADOR MOTOROLA DVR DCX-3520 | B84: 4007967
A85: DECODIFICADOR MOTOROLA DVR DCX-3520 | B85: 4007967
A86: DECODIFICADOR MOTOROLA DVR DCX-3520 | B86: 4007967
A88: DECODIFICADOR MOTOROLA HD DCX-525 (SKU 4007984)
A89: PRODUCTO | B89: SKU | C89: SERIE | D89: MAC EMTA | E89: MAC UA
A90: DECODIFICADOR MOTOROLA HD DCX-525 | B90: 4007984
A91: DECODIFICADOR MOTOROLA HD DCX-525 | B91: 4007984
A92: DECODIFICADOR MOTOROLA HD DCX-525 | B92: 4007984
...
